{
 "cells": [
  {
   "cell_type": "markdown",
   "id": "390e57f3",
   "metadata": {},
   "source": [
    "### Trade Demo\n",
    "\n",
    "#### Goals:\n",
    "- Login to the Canada domain.\n",
    "- Select the dataset.\n",
    "- Cacluate the sum of total of good imported to Egypt.\n",
    "- Publish the result\n",
    "- Download the results"
   ]
  },
  {
   "cell_type": "markdown",
   "id": "61b3dd4a",
   "metadata": {},
   "source": [
    "### Step 1: Login into the Canada domain"
   ]
  },
  {
   "cell_type": "code",
   "execution_count": null,
   "id": "dbcce57a",
   "metadata": {
    "scrolled": true
   },
   "outputs": [
    {
     "name": "stderr",
     "output_type": "stream",
     "text": [
      "ERROR:root:Internal Python error in the inspect module.\n",
      "Below is the traceback from this internal error.\n",
      "\n",
      "ERROR:root:Internal Python error in the inspect module.\n",
      "Below is the traceback from this internal error.\n",
      "\n",
      "ERROR:root:Internal Python error in the inspect module.\n",
      "Below is the traceback from this internal error.\n",
      "\n"
     ]
    },
    {
     "name": "stdout",
     "output_type": "stream",
     "text": [
      "Traceback (most recent call last):\n",
      "  File \"/home/user/anaconda3/envs/pysyft/lib/python3.9/site-packages/IPython/core/interactiveshell.py\", line 3437, in run_code\n",
      "    exec(code_obj, self.user_global_ns, self.user_ns)\n",
      "  File \"<ipython-input-1-5fcbed5e7940>\", line 5, in <module>\n",
      "    import syft as sy\n",
      "ModuleNotFoundError: No module named 'syft'\n",
      "\n",
      "During handling of the above exception, another exception occurred:\n",
      "\n",
      "Traceback (most recent call last):\n",
      "  File \"/home/user/anaconda3/envs/pysyft/lib/python3.9/site-packages/IPython/core/interactiveshell.py\", line 2061, in showtraceback\n",
      "    stb = value._render_traceback_()\n",
      "AttributeError: 'ModuleNotFoundError' object has no attribute '_render_traceback_'\n",
      "\n",
      "During handling of the above exception, another exception occurred:\n",
      "\n",
      "Traceback (most recent call last):\n",
      "  File \"/home/user/anaconda3/envs/pysyft/lib/python3.9/site-packages/IPython/core/ultratb.py\", line 1101, in get_records\n",
      "    return _fixed_getinnerframes(etb, number_of_lines_of_context, tb_offset)\n",
      "ERROR! Session/line number was not unique in  File \"/home/user/anaconda3/envs/pysyft/lib/python3.9/site-packages/IPython/core/ultratb.py\", line 248, in wrapped\n",
      "    return f(*args, **kwargs)\n",
      "  File \"/home/user/anaconda3/envs/pysyft/lib/python3.9/site-packages/IPython/core/ultratb.py\", line 281, in _fixed_getinnerframes\n",
      "    records = fix_frame_records_filenames(inspect.getinnerframes(etb, context))\n",
      "  File \"/home/user/anaconda3/envs/pysyft/lib/python3.9/inspect.py\", line 1541, in getinnerframes\n",
      "    frameinfo = (tb.tb_frame,) + getframeinfo(tb, context)\n",
      "  File \"/home/user/anaconda3/envs/pysyft/lib/python3.9/inspect.py\", line 1499, in getframeinfo\n",
      "    filename = getsourcefile(frame) or getfile(frame)\n",
      "  File \"/home/user/anaconda3/envs/pysyft/lib/python3.9/inspect.py\", line 709, in getsourcefile\n",
      "    if getattr(getmodule(object, filename), '__loader__', None) is not None:\n",
      "  File \"/home/user/anaconda3/envs/pysyft/lib/python3.9/inspect.py\", line 738, in getmodule\n",
      "    file = getabsfile(object, _filename)\n",
      "  File \"/home/user/anaconda3/envs/pysyft/lib/python3.9/inspect.py\", line 722, in getabsfile\n",
      "    return os.path.normcase(os.path.abspath(_filename))\n",
      "  File \"/home/user/anaconda3/envs/pysyft/lib/python3.9/posixpath.py\", line 379, in abspath\n",
      "    cwd = os.getcwd()\n",
      "FileNotFoundError: [Errno 2] No such file or directory\n",
      " database. History logging moved to new session 311\n",
      "Traceback (most recent call last):\n",
      "  File \"/home/user/anaconda3/envs/pysyft/lib/python3.9/site-packages/IPython/core/interactiveshell.py\", line 3437, in run_code\n",
      "    exec(code_obj, self.user_global_ns, self.user_ns)\n",
      "  File \"<ipython-input-1-5fcbed5e7940>\", line 5, in <module>\n",
      "    import syft as sy\n",
      "ModuleNotFoundError: No module named 'syft'\n",
      "\n",
      "During handling of the above exception, another exception occurred:\n",
      "\n",
      "Traceback (most recent call last):\n",
      "  File \"/home/user/anaconda3/envs/pysyft/lib/python3.9/site-packages/IPython/core/interactiveshell.py\", line 2061, in showtraceback\n",
      "    stb = value._render_traceback_()\n",
      "AttributeError: 'ModuleNotFoundError' object has no attribute '_render_traceback_'\n",
      "\n",
      "During handling of the above exception, another exception occurred:\n",
      "\n",
      "Traceback (most recent call last):\n",
      "  File \"/home/user/anaconda3/envs/pysyft/lib/python3.9/site-packages/IPython/core/interactiveshell.py\", line 3357, in run_ast_nodes\n",
      "    if (await self.run_code(code, result,  async_=asy)):\n",
      "  File \"/home/user/anaconda3/envs/pysyft/lib/python3.9/site-packages/IPython/core/interactiveshell.py\", line 3454, in run_code\n",
      "    self.showtraceback(running_compiled_code=True)\n",
      "  File \"/home/user/anaconda3/envs/pysyft/lib/python3.9/site-packages/IPython/core/interactiveshell.py\", line 2063, in showtraceback\n",
      "    stb = self.InteractiveTB.structured_traceback(etype,\n",
      "  File \"/home/user/anaconda3/envs/pysyft/lib/python3.9/site-packages/IPython/core/ultratb.py\", line 1367, in structured_traceback\n",
      "    return FormattedTB.structured_traceback(\n",
      "  File \"/home/user/anaconda3/envs/pysyft/lib/python3.9/site-packages/IPython/core/ultratb.py\", line 1267, in structured_traceback\n",
      "    return VerboseTB.structured_traceback(\n",
      "  File \"/home/user/anaconda3/envs/pysyft/lib/python3.9/site-packages/IPython/core/ultratb.py\", line 1124, in structured_traceback\n",
      "    formatted_exception = self.format_exception_as_a_whole(etype, evalue, etb, number_of_lines_of_context,\n",
      "  File \"/home/user/anaconda3/envs/pysyft/lib/python3.9/site-packages/IPython/core/ultratb.py\", line 1082, in format_exception_as_a_whole\n",
      "    last_unique, recursion_repeat = find_recursion(orig_etype, evalue, records)\n",
      "  File \"/home/user/anaconda3/envs/pysyft/lib/python3.9/site-packages/IPython/core/ultratb.py\", line 382, in find_recursion\n",
      "    return len(records), 0\n",
      "TypeError: object of type 'NoneType' has no len()\n",
      "\n",
      "During handling of the above exception, another exception occurred:\n",
      "\n",
      "Traceback (most recent call last):\n",
      "  File \"/home/user/anaconda3/envs/pysyft/lib/python3.9/site-packages/IPython/core/interactiveshell.py\", line 2061, in showtraceback\n",
      "    stb = value._render_traceback_()\n",
      "AttributeError: 'TypeError' object has no attribute '_render_traceback_'\n",
      "\n",
      "During handling of the above exception, another exception occurred:\n",
      "\n",
      "Traceback (most recent call last):\n",
      "  File \"/home/user/anaconda3/envs/pysyft/lib/python3.9/site-packages/IPython/core/ultratb.py\", line 1101, in get_records\n",
      "    return _fixed_getinnerframes(etb, number_of_lines_of_context, tb_offset)\n",
      "  File \"/home/user/anaconda3/envs/pysyft/lib/python3.9/site-packages/IPython/core/ultratb.py\", line 248, in wrapped\n",
      "    return f(*args, **kwargs)\n",
      "  File \"/home/user/anaconda3/envs/pysyft/lib/python3.9/site-packages/IPython/core/ultratb.py\", line 281, in _fixed_getinnerframes\n",
      "    records = fix_frame_records_filenames(inspect.getinnerframes(etb, context))\n",
      "  File \"/home/user/anaconda3/envs/pysyft/lib/python3.9/inspect.py\", line 1541, in getinnerframes\n",
      "    frameinfo = (tb.tb_frame,) + getframeinfo(tb, context)\n",
      "  File \"/home/user/anaconda3/envs/pysyft/lib/python3.9/inspect.py\", line 1499, in getframeinfo\n",
      "    filename = getsourcefile(frame) or getfile(frame)\n",
      "  File \"/home/user/anaconda3/envs/pysyft/lib/python3.9/inspect.py\", line 709, in getsourcefile\n",
      "    if getattr(getmodule(object, filename), '__loader__', None) is not None:\n",
      "  File \"/home/user/anaconda3/envs/pysyft/lib/python3.9/inspect.py\", line 738, in getmodule\n",
      "    file = getabsfile(object, _filename)\n",
      "  File \"/home/user/anaconda3/envs/pysyft/lib/python3.9/inspect.py\", line 722, in getabsfile\n",
      "    return os.path.normcase(os.path.abspath(_filename))\n",
      "  File \"/home/user/anaconda3/envs/pysyft/lib/python3.9/posixpath.py\", line 379, in abspath\n",
      "    cwd = os.getcwd()\n",
      "FileNotFoundError: [Errno 2] No such file or directory\n",
      "Traceback (most recent call last):\n",
      "  File \"/home/user/anaconda3/envs/pysyft/lib/python3.9/site-packages/IPython/core/interactiveshell.py\", line 3437, in run_code\n",
      "    exec(code_obj, self.user_global_ns, self.user_ns)\n",
      "  File \"<ipython-input-1-5fcbed5e7940>\", line 5, in <module>\n",
      "    import syft as sy\n",
      "ModuleNotFoundError: No module named 'syft'\n",
      "\n",
      "During handling of the above exception, another exception occurred:\n",
      "\n",
      "Traceback (most recent call last):\n",
      "  File \"/home/user/anaconda3/envs/pysyft/lib/python3.9/site-packages/IPython/core/interactiveshell.py\", line 2061, in showtraceback\n",
      "    stb = value._render_traceback_()\n",
      "AttributeError: 'ModuleNotFoundError' object has no attribute '_render_traceback_'\n",
      "\n",
      "During handling of the above exception, another exception occurred:\n",
      "\n",
      "Traceback (most recent call last):\n",
      "  File \"/home/user/anaconda3/envs/pysyft/lib/python3.9/site-packages/IPython/core/interactiveshell.py\", line 3357, in run_ast_nodes\n",
      "    if (await self.run_code(code, result,  async_=asy)):\n",
      "  File \"/home/user/anaconda3/envs/pysyft/lib/python3.9/site-packages/IPython/core/interactiveshell.py\", line 3454, in run_code\n",
      "    self.showtraceback(running_compiled_code=True)\n",
      "  File \"/home/user/anaconda3/envs/pysyft/lib/python3.9/site-packages/IPython/core/interactiveshell.py\", line 2063, in showtraceback\n",
      "    stb = self.InteractiveTB.structured_traceback(etype,\n",
      "  File \"/home/user/anaconda3/envs/pysyft/lib/python3.9/site-packages/IPython/core/ultratb.py\", line 1367, in structured_traceback\n",
      "    return FormattedTB.structured_traceback(\n",
      "  File \"/home/user/anaconda3/envs/pysyft/lib/python3.9/site-packages/IPython/core/ultratb.py\", line 1267, in structured_traceback\n",
      "    return VerboseTB.structured_traceback(\n",
      "  File \"/home/user/anaconda3/envs/pysyft/lib/python3.9/site-packages/IPython/core/ultratb.py\", line 1124, in structured_traceback\n",
      "    formatted_exception = self.format_exception_as_a_whole(etype, evalue, etb, number_of_lines_of_context,\n",
      "  File \"/home/user/anaconda3/envs/pysyft/lib/python3.9/site-packages/IPython/core/ultratb.py\", line 1082, in format_exception_as_a_whole\n",
      "    last_unique, recursion_repeat = find_recursion(orig_etype, evalue, records)\n",
      "  File \"/home/user/anaconda3/envs/pysyft/lib/python3.9/site-packages/IPython/core/ultratb.py\", line 382, in find_recursion\n",
      "    return len(records), 0\n",
      "TypeError: object of type 'NoneType' has no len()\n",
      "\n",
      "During handling of the above exception, another exception occurred:\n",
      "\n",
      "Traceback (most recent call last):\n",
      "  File \"/home/user/anaconda3/envs/pysyft/lib/python3.9/site-packages/IPython/core/interactiveshell.py\", line 2061, in showtraceback\n",
      "    stb = value._render_traceback_()\n",
      "AttributeError: 'TypeError' object has no attribute '_render_traceback_'\n",
      "\n",
      "During handling of the above exception, another exception occurred:\n",
      "\n",
      "Traceback (most recent call last):\n",
      "  File \"/home/user/anaconda3/envs/pysyft/lib/python3.9/site-packages/IPython/core/interactiveshell.py\", line 2940, in _run_cell\n",
      "    return runner(coro)\n",
      "  File \"/home/user/anaconda3/envs/pysyft/lib/python3.9/site-packages/IPython/core/async_helpers.py\", line 68, in _pseudo_sync_runner\n",
      "    coro.send(None)\n",
      "  File \"/home/user/anaconda3/envs/pysyft/lib/python3.9/site-packages/IPython/core/interactiveshell.py\", line 3165, in run_cell_async\n",
      "    has_raised = await self.run_ast_nodes(code_ast.body, cell_name,\n",
      "  File \"/home/user/anaconda3/envs/pysyft/lib/python3.9/site-packages/IPython/core/interactiveshell.py\", line 3376, in run_ast_nodes\n",
      "    self.showtraceback()\n",
      "  File \"/home/user/anaconda3/envs/pysyft/lib/python3.9/site-packages/IPython/core/interactiveshell.py\", line 2063, in showtraceback\n",
      "    stb = self.InteractiveTB.structured_traceback(etype,\n",
      "  File \"/home/user/anaconda3/envs/pysyft/lib/python3.9/site-packages/IPython/core/ultratb.py\", line 1367, in structured_traceback\n",
      "    return FormattedTB.structured_traceback(\n",
      "  File \"/home/user/anaconda3/envs/pysyft/lib/python3.9/site-packages/IPython/core/ultratb.py\", line 1267, in structured_traceback\n",
      "    return VerboseTB.structured_traceback(\n",
      "  File \"/home/user/anaconda3/envs/pysyft/lib/python3.9/site-packages/IPython/core/ultratb.py\", line 1142, in structured_traceback\n",
      "    formatted_exceptions += self.format_exception_as_a_whole(etype, evalue, etb, lines_of_context,\n",
      "  File \"/home/user/anaconda3/envs/pysyft/lib/python3.9/site-packages/IPython/core/ultratb.py\", line 1082, in format_exception_as_a_whole\n",
      "    last_unique, recursion_repeat = find_recursion(orig_etype, evalue, records)\n",
      "  File \"/home/user/anaconda3/envs/pysyft/lib/python3.9/site-packages/IPython/core/ultratb.py\", line 382, in find_recursion\n",
      "    return len(records), 0\n",
      "TypeError: object of type 'NoneType' has no len()\n",
      "\n",
      "During handling of the above exception, another exception occurred:\n",
      "\n",
      "Traceback (most recent call last):\n",
      "  File \"/home/user/anaconda3/envs/pysyft/lib/python3.9/site-packages/IPython/core/interactiveshell.py\", line 2061, in showtraceback\n",
      "    stb = value._render_traceback_()\n",
      "AttributeError: 'TypeError' object has no attribute '_render_traceback_'\n",
      "\n",
      "During handling of the above exception, another exception occurred:\n",
      "\n",
      "Traceback (most recent call last):\n",
      "  File \"/home/user/anaconda3/envs/pysyft/lib/python3.9/site-packages/IPython/core/ultratb.py\", line 1101, in get_records\n",
      "    return _fixed_getinnerframes(etb, number_of_lines_of_context, tb_offset)\n",
      "  File \"/home/user/anaconda3/envs/pysyft/lib/python3.9/site-packages/IPython/core/ultratb.py\", line 248, in wrapped\n",
      "    return f(*args, **kwargs)\n",
      "  File \"/home/user/anaconda3/envs/pysyft/lib/python3.9/site-packages/IPython/core/ultratb.py\", line 281, in _fixed_getinnerframes\n",
      "    records = fix_frame_records_filenames(inspect.getinnerframes(etb, context))\n",
      "  File \"/home/user/anaconda3/envs/pysyft/lib/python3.9/inspect.py\", line 1541, in getinnerframes\n",
      "    frameinfo = (tb.tb_frame,) + getframeinfo(tb, context)\n",
      "  File \"/home/user/anaconda3/envs/pysyft/lib/python3.9/inspect.py\", line 1499, in getframeinfo\n",
      "    filename = getsourcefile(frame) or getfile(frame)\n",
      "  File \"/home/user/anaconda3/envs/pysyft/lib/python3.9/inspect.py\", line 709, in getsourcefile\n",
      "    if getattr(getmodule(object, filename), '__loader__', None) is not None:\n",
      "  File \"/home/user/anaconda3/envs/pysyft/lib/python3.9/inspect.py\", line 738, in getmodule\n",
      "    file = getabsfile(object, _filename)\n",
      "  File \"/home/user/anaconda3/envs/pysyft/lib/python3.9/inspect.py\", line 722, in getabsfile\n",
      "    return os.path.normcase(os.path.abspath(_filename))\n",
      "  File \"/home/user/anaconda3/envs/pysyft/lib/python3.9/posixpath.py\", line 379, in abspath\n",
      "    cwd = os.getcwd()\n",
      "FileNotFoundError: [Errno 2] No such file or directory\n"
     ]
    }
   ],
   "source": [
    "# As a Data Scientist we want to perform some analysis on the trade dataset available on the Canada domain.\n",
    "# Our goal is to calculate the sum total of the goods imported (imports + re-imports) \n",
    "# and exported (exports + re-exports) to Egypt.\n",
    "\n",
    "import syft as sy\n",
    "\n",
    "# Let's login into the canada domain\n",
    "canada_domain_node = sy.login(email=\"sheldon@caltech.edu\", password=\"bazinga\", port=8081)"
   ]
  },
  {
   "cell_type": "markdown",
   "id": "72d92c1b",
   "metadata": {},
   "source": [
    "### Step 2: Select the dataset"
   ]
  },
  {
   "cell_type": "code",
   "execution_count": null,
   "id": "66714cf0",
   "metadata": {},
   "outputs": [],
   "source": [
    "# Awesome !!! We're logged into the domain node\n",
    "# Let's quickly list all the datasets available on the Canada domain\n",
    "\n",
    "canada_domain_node.datasets"
   ]
  },
  {
   "cell_type": "code",
   "execution_count": null,
   "id": "eac1bd20-1314-4efb-8a3b-b395f909f336",
   "metadata": {},
   "outputs": [],
   "source": [
    "canada_domain_node.datasets[0]"
   ]
  },
  {
   "cell_type": "code",
   "execution_count": null,
   "id": "2b163b3d-e7f2-449c-a17f-162b4cf9a579",
   "metadata": {},
   "outputs": [],
   "source": [
    "feb2020 = canada_domain_node.datasets[0]['feb2020']\n",
    "feb2020.tags"
   ]
  },
  {
   "cell_type": "code",
   "execution_count": null,
   "id": "04a33945",
   "metadata": {},
   "outputs": [],
   "source": [
    "# # Let's try to get the whole dataset itself.\n",
    "feb2020.request(reason=\"Access whole dataset\")"
   ]
  },
  {
   "cell_type": "markdown",
   "id": "d62b4dd0-dcb8-47ba-a50d-1f50b7972922",
   "metadata": {},
   "source": [
    "#### STOP: Return to Data Owner-Canada.ipynb - STEP 7!!\n",
    "\n",
    "### Step 3: Try to download the whole dataset"
   ]
  },
  {
   "cell_type": "code",
   "execution_count": null,
   "id": "faa69f06",
   "metadata": {},
   "outputs": [],
   "source": [
    "# Let's see if our request was accepted\n",
    "feb2020.get()"
   ]
  },
  {
   "cell_type": "code",
   "execution_count": null,
   "id": "62d5192b",
   "metadata": {},
   "outputs": [],
   "source": [
    "# Seems, like the request to download the whole dataset was denied by the Data Owner."
   ]
  },
  {
   "cell_type": "markdown",
   "id": "abc44443-9da4-48a0-a1e4-fa6afe01a0e6",
   "metadata": {},
   "source": [
    "### Step 4: Private - Public Mutiplication"
   ]
  },
  {
   "cell_type": "code",
   "execution_count": null,
   "id": "cc351052",
   "metadata": {},
   "outputs": [],
   "source": [
    "# Let's continue with the analysis remotely.\n",
    "# Let's calculate the value of the goods import from Egypt.\n",
    "\n",
    "value_of_goods_imported_from_egypt = feb2020[(feb2020['Partner'] == 'Egypt') & (feb2020['Trade Flow'] == 'Imports')]['Trade Value (US$)'].sum()\n",
    "\n",
    "private_masking = feb2020[(feb2020['Partner'] == 'Egypt') & (feb2020['Trade Flow'] == 'Imports')]\n",
    "public_mask = private_masking.publish(sigma=0.1).get()\n",
    "value_of_goods_reimported_from_egypt = feb2020['Trade Value'] * public_mask\n",
    "\n",
    "value_of_goods_reimported_from_egypt_in_thousands = value_of_goods_reimported_from_egypt * (0.001)"
   ]
  },
  {
   "cell_type": "markdown",
   "id": "04e10c2d",
   "metadata": {},
   "source": [
    "### Step 5: Private - Private Addition"
   ]
  },
  {
   "cell_type": "code",
   "execution_count": null,
   "id": "f6057957",
   "metadata": {},
   "outputs": [],
   "source": [
    "# Great !!!, Now that we have performed the analysis, let's publish our results.\n",
    "# sigma -> Amount of noise added to the response (0 <= sigma <= 1)\n",
    "# Larger the sigma, smaller the budget spent.\n",
    "\n",
    "private_total_imported_goods_value = public_value_of_goods_reimported_from_egypt + public_value_of_goods_imported_from_egypt\n",
    "private_total_imported_goods_value = private_total_imported_goods_value.sum()\n",
    "public_total_imported_goods_value = private_total_imported_goods_value.publish(sigma=0.3)"
   ]
  },
  {
   "cell_type": "code",
   "execution_count": null,
   "id": "1c72d606",
   "metadata": {},
   "outputs": [],
   "source": []
  },
  {
   "cell_type": "markdown",
   "id": "513a6e7f-9f37-459b-9369-03154e23a951",
   "metadata": {},
   "source": [
    "### Step 6: Download Results"
   ]
  },
  {
   "cell_type": "code",
   "execution_count": null,
   "id": "f8725460",
   "metadata": {},
   "outputs": [],
   "source": [
    "# Let's download the results"
   ]
  },
  {
   "cell_type": "code",
   "execution_count": null,
   "id": "545a1edd",
   "metadata": {},
   "outputs": [],
   "source": [
    "total_imported_goods_value = public_total_imported_goods_value.get()\n",
    "print(f\"Total trade value($) of the goods Imported from Egypt to Canada: ${total_imported_goods_value}\")"
   ]
  },
  {
   "cell_type": "markdown",
   "id": "6ed7a86a",
   "metadata": {},
   "source": [
    "*Great !!! We successfully, finished our analysis.*"
   ]
  },
  {
   "cell_type": "markdown",
   "id": "07e0cee6-cc7d-4f55-a79c-038e3e6fc8e2",
   "metadata": {},
   "source": [
    "# CONGRATULATIONS!!!\n",
    "\n",
    "You've finished the demo!"
   ]
  }
 ],
 "metadata": {
  "kernelspec": {
   "display_name": "Python 3 (ipykernel)",
   "language": "python",
   "name": "python3"
  },
  "language_info": {
   "codemirror_mode": {
    "name": "ipython",
    "version": 3
   },
   "file_extension": ".py",
   "mimetype": "text/x-python",
   "name": "python",
   "nbconvert_exporter": "python",
   "pygments_lexer": "ipython3",
   "version": "3.9.6"
  }
 },
 "nbformat": 4,
 "nbformat_minor": 5
}
